Workbook

Sheet Dashboard_General
A1: GEESNA | Dashboard General de Órdenes a Proveedores
A3: Nota: | B3: Los semáforos de cada orden avanzan según estas etapas: Cotizar, Aprobar, Info empaque, Anticipo, Producción, Sale puerto origen, Llega puerto MX, Llega a bodega.
A5: Órdenes totales | D5: Monto total | G5: Órdenes completas
A6: =SUM(B12:B21) -> 0 | D6: =SUM(C12:C21) -> 490792.7 | G6: =SUM(D12:D21) -> 0
A8: Órdenes activas | D8: Órdenes en rojo | G8: % avance promedio
A9: =SUM(E12:E21) -> 0 | D9: =SUM(F12:F21) -> 257 | G9: =IFERROR(AVERAGE(G12:G21),0) -> 0
A11: Proveedor | B11: Órdenes | C11: Monto total | D11: Completas | E11: Activas | F11: En rojo | G11: % avance prom. | H11: Próx. ETA bodega | I11: Acción | K11: Semáforo general | L11: Caja comprometida
A12: Fine Creations | B12: ='FINE CREATIONS'!B5 | C12: ='FINE CREATIONS'!D5 -> 390000 | D12: ='FINE CREATIONS'!G5 | E12: ='FINE CREATIONS'!I5 | F12: ='FINE CREATIONS'!K5 -> 6 | G12: ='FINE CREATIONS'!M5 | H12: ='FINE CREATIONS'!O5 | I12: =IF(F12>0,"Escalar atrasos",IF(E12>0,"Dar seguimiento","Estable")) -> Escalar atrasos | K12: =IF(SUM(F12:F21)>0,"ROJO",IF(SUM(E12:E21)>0,"AMARILLO","VERDE")) -> ROJO | L12: =SUM(C12:C21) -> 490792.7
A13: Lina | B13: ='CANPY LINA'!B5 | C13: ='CANPY LINA'!D5 -> 100792.7 | D13: ='CANPY LINA'!F5 | E13: ='CANPY LINA'!H5 | F13: ='CANPY LINA'!J5 -> 11 | G13: ='CANPY LINA'!L5 | H13: ='CANPY LINA'!N5 | I13: =IF(F13>0,"Escalar atrasos",IF(E13>0,"Dar seguimiento","Estable")) -> Escalar atrasos
A14: Proveedor 3 | B14: =Prov_3!B5 | C14: =Prov_3!D5 -> 0 | D14: =Prov_3!F5 | E14: =Prov_3!H5 | F14: =Prov_3!J5 -> 30 | G14: =Prov_3!L5 | H14: =Prov_3!N5 | I14: =IF(F14>0,"Escalar atrasos",IF(E14>0,"Dar seguimiento","Estable")) -> Escalar atrasos
A15: Proveedor 4 | B15: =Prov_4!B5 | C15: =Prov_4!D5 -> 0 | D15: =Prov_4!F5 | E15: =Prov_4!H5 | F15: =Prov_4!J5 -> 30 | G15: =Prov_4!L5 | H15: =Prov_4!N5 | I15: =IF(F15>0,"Escalar atrasos",IF(E15>0,"Dar seguimiento","Estable")) -> Escalar atrasos
A16: Proveedor 5 | B16: =Prov_5!B5 | C16: =Prov_5!D5 -> 0 | D16: =Prov_5!F5 | E16: =Prov_5!H5 | F16: =Prov_5!J5 -> 30 | G16: =Prov_5!L5 | H16: =Prov_5!N5 | I16: =IF(F16>0,"Escalar atrasos",IF(E16>0,"Dar seguimiento","Estable")) -> Escalar atrasos
A17: Proveedor 6 | B17: =Prov_6!B5 | C17: =Prov_6!D5 -> 0 | D17: =Prov_6!F5 | E17: =Prov_6!H5 | F17: =Prov_6!J5 -> 30 | G17: =Prov_6!L5 | H17: =Prov_6!N5 | I17: =IF(F17>0,"Escalar atrasos",IF(E17>0,"Dar seguimiento","Estable")) -> Escalar atrasos
A18: Proveedor 7 | B18: =Prov_7!B5 | C18: =Prov_7!D5 -> 0 | D18: =Prov_7!F5 | E18: =Prov_7!H5 | F18: =Prov_7!J5 -> 30 | G18: =Prov_7!L5 | H18: =Prov_7!N5 | I18: =IF(F18>0,"Escalar atrasos",IF(E18>0,"Dar seguimiento","Estable")) -> Escalar atrasos
A19: Proveedor 8 | B19: =Prov_8!B5 | C19: =Prov_8!D5 -> 0 | D19: =Prov_8!F5 | E19: =Prov_8!H5 | F19: =Prov_8!J5 -> 30 | G19: =Prov_8!L5 | H19: =Prov_8!N5 | I19: =IF(F19>0,"Escalar atrasos",IF(E19>0,"Dar seguimiento","Estable")) -> Escalar atrasos
A20: Proveedor 9 | B20: =Prov_9!B5 | C20: =Prov_9!D5 -> 0 | D20: =Prov_9!F5 | E20: =Prov_9!H5 | F20: =Prov_9!J5 -> 30 | G20: =Prov_9!L5 | H20: =Prov_9!N5 | I20: =IF(F20>0,"Escalar atrasos",IF(E20>0,"Dar seguimiento","Estable")) -> Escalar atrasos
A21: Proveedor 10 | B21: =Prov_10!B5 | C21: =Prov_10!D5 -> 0 | D21: =Prov_10!F5 | E21: =Prov_10!H5 | F21: =Prov_10!J5 -> 30 | G21: =Prov_10!L5 | H21: =Prov_10!N5 | I21: =IF(F21>0,"Escalar atrasos",IF(E21>0,"Dar seguimiento","Estable")) -> Escalar atrasos
G48: rihanna songs

Sheet Flujo_Caja_Compras
A1: GEESNA | Flujo de Caja de Inventario y Compras
A4: Mes | B4: Proveedor | C4: Orden ID | D4: Monto Orden | E4: Anticipo | F4: Saldo | G4: Fecha anticipo | H4: ETA Puerto MX | I4: ETA Bodega | J4: Notas

Sheet FINE CREATIONS
A1: GEESNA | Control de Órdenes de Contenedor - FINE CREATIONS I JEREMY
A3: Proveedor | B3: Fine Creations | D3: Contacto | H3: País | I3: China | K3: Responsable
A4: Órdenes | D4: Monto total | H4: Completas | K4: Activas | N4: En rojo | Q4: % avance prom. | T4: Próx. ETA bodega | W4: BALANCE
A5: =COUNTIF(A11:A40,"<>") -> 6 | D5: =SUM(E11:E40) -> 390000 | H5: =COUNTIF(S11:S40,"COMPLETA") -> 0 | K5: =COUNTIFS(S11:S40,"<>COMPLETA",A11:A40,"<>") -> 6 | N5: =COUNTIF(U11:U40,"ROJO") -> 0 | Q5: =IFERROR(AVERAGE(T11:T40),0) -> 0 | T5: =IFERROR(MINIFS(H11:H40,S11:S40,"<>COMPLETA",H11:H40,">0"),0) -> 46147 | W5: =SUM(E11:E37)-SUM(W11:W31) -> 380000
A8: Semáforo proveedor | B8: =IF(K5>0,"ROJO",IF(I5>0,"AMARILLO","VERDE")) -> ROJO | D8: Siguiente acción | E8: =IF(B8="ROJO","Escalar órdenes vencidas",IF(B8="AMARILLO","Monitorear órdenes activas","Operación estable")) -> Escalar órdenes vencidas
A10: Orden ID | B10: Producto / SKU | C10: Contenedor | D10: Responsable | E10: Monto Orden | F10: ETA Mercancia Lista | G10: ETA Puerto MX | H10: ETA Bodega | I10: Cotizar | J10: Aprobar | K10: Info empaque | L10: Anticipo | M10: Producción OK | N10: Sale puerto origen | O10: Llega puerto MX | P10: Llega bodega | Q10: Etapa actual | R10: Estado orden | S10: % avance | T10: Semáforo | U10: Días sin movimiento | V10: Notas | W10: Pagos
A11: PB2020251013 | B11: RED / GEN / 80 | C11: MSCU1234 | D11: Gerardo | E11: 50000 | F11: 46145 | G11: 46146 | H11: 46147 | I11: listo | J11: aprobado | K11: enviada | L11: enviada | M11: ok | Q11: =IF(P11<>"","Llega bodega",IF(O11<>"","Llega puerto MX",IF(N11<>"","Sale puerto origen",IF(M11<>"","Producción OK",IF(L11<>"","Anticipo",IF(K11<>"","Info empaque",IF(J11<>"","Aprobar",IF(I11<>"","Cotizar","Sin iniciar")))))))) -> Producción OK | R11: =IF(A11="","",IF(P11<>"","COMPLETA",IF(N11<>"","EN TRÁNSITO",IF(M11<>"","EN PRODUCCIÓN",IF(L11<>"","PAGADA / EN ESPERA","EN GESTIÓN"))))) -> EN PRODUCCIÓN | S11: =COUNT(I11:P11)/8 -> 0 | T11: =IF(A11="","",IF(P11<>"","VERDE",IF(AND(H11<>"",TODAY()>H11),"ROJO",IF(COUNT(I11:P11)=0,"GRIS","AMARILLO")))) -> ROJO | U11: =IF(COUNT(I11:P11)=0,"",TODAY()-MAX(I11:P11)) | W11: 10000
A12: PB2020251014-A | B12: NAR / PRO / 180 | C12: MSCU1235 | D12: Gerardo | E12: 70000 | F12: 46146 | G12: 46147 | H12: 46165 | I12: listo | J12: aprobado | Q12: =IF(P12<>"","Llega bodega",IF(O12<>"","Llega puerto MX",IF(N12<>"","Sale puerto origen",IF(M12<>"","Producción OK",IF(L12<>"","Anticipo",IF(K12<>"","Info empaque",IF(J12<>"","Aprobar",IF(I12<>"","Cotizar","Sin iniciar")))))))) -> Aprobar | R12: =IF(A12="","",IF(P12<>"","COMPLETA",IF(N12<>"","EN TRÁNSITO",IF(M12<>"","EN PRODUCCIÓN",IF(L12<>"","PAGADA / EN ESPERA","EN GESTIÓN"))))) -> EN GESTIÓN | S12: =COUNT(I12:P12)/8 -> 0 | T12: =IF(A12="","",IF(P12<>"","VERDE",IF(AND(H12<>"",TODAY()>H12),"ROJO",IF(COUNT(I12:P12)=0,"GRIS","AMARILLO")))) -> ROJO | U12: =IF(COUNT(I12:P12)=0,"",TODAY()-MAX(I12:P12))
A13: PB2020251014-B | B13: BLUE / PRO / 180 | C13: MSCU1236 | D13: Gerardo | E13: 70000 | F13: 46122 | G13: 46157 | H13: 46221 | I13: listo | J13: aprobado | K13: enviado | L13: emviado | M13: ok | N13: ya salio | O13: 46228 | P13: 415061 | Q13: =IF(P13<>"","Llega bodega",IF(O13<>"","Llega puerto MX",IF(N13<>"","Sale puerto origen",IF(M13<>"","Producción OK",IF(L13<>"","Anticipo",IF(K13<>"","Info empaque",IF(J13<>"","Aprobar",IF(I13<>"","Cotizar","Sin iniciar")))))))) -> Llega bodega | R13: =IF(A13="","",IF(P13<>"","COMPLETA",IF(N13<>"","EN TRÁNSITO",IF(M13<>"","EN PRODUCCIÓN",IF(L13<>"","PAGADA / EN ESPERA","EN GESTIÓN"))))) -> COMPLETA | S13: =COUNT(I13:P13)/8 -> 0.25 | T13: =IF(A13="","",IF(P13<>"","VERDE",IF(AND(H13<>"",TODAY()>H13),"ROJO",IF(COUNT(I13:P13)=0,"GRIS","AMARILLO")))) -> VERDE | U13: =IF(COUNT(I13:P13)=0,"",TODAY()-MAX(I13:P13)) -> -368889
A14: PB2020251119 | B14: MIX | C14: MSCU1237 | D14: Gerardo | E14: 90000 | F14: 46123 | G14: 46158 | H14: 46222 | I14: listo | P14: 46057 | Q14: =IF(P14<>"","Llega bodega",IF(O14<>"","Llega puerto MX",IF(N14<>"","Sale puerto origen",IF(M14<>"","Producción OK",IF(L14<>"","Anticipo",IF(K14<>"","Info empaque",IF(J14<>"","Aprobar",IF(I14<>"","Cotizar","Sin iniciar")))))))) -> Llega bodega | R14: =IF(A14="","",IF(P14<>"","COMPLETA",IF(N14<>"","EN TRÁNSITO",IF(M14<>"","EN PRODUCCIÓN",IF(L14<>"","PAGADA / EN ESPERA","EN GESTIÓN"))))) -> COMPLETA | S14: =COUNT(I14:P14)/8 -> 0.125 | T14: =IF(A14="","",IF(P14<>"","VERDE",IF(AND(H14<>"",TODAY()>H14),"ROJO",IF(COUNT(I14:P14)=0,"GRIS","AMARILLO")))) -> VERDE | U14: =IF(COUNT(I14:P14)=0,"",TODAY()-MAX(I14:P14)) -> 115
A15: PB2020251128 | B15: NAR / GEN / 80 | C15: MSCU1238 | E15: 110000 | F15: 46124 | G15: 46159 | H15: 46223 | Q15: =IF(P15<>"","Llega bodega",IF(O15<>"","Llega puerto MX",IF(N15<>"","Sale puerto origen",IF(M15<>"","Producción OK",IF(L15<>"","Anticipo",IF(K15<>"","Info empaque",IF(J15<>"","Aprobar",IF(I15<>"","Cotizar","Sin iniciar")))))))) -> Sin iniciar | R15: =IF(A15="","",IF(P15<>"","COMPLETA",IF(N15<>"","EN TRÁNSITO",IF(M15<>"","EN PRODUCCIÓN",IF(L15<>"","PAGADA / EN ESPERA","EN GESTIÓN"))))) -> EN GESTIÓN | S15: =COUNT(I15:P15)/8 -> 0 | T15: =IF(A15="","",IF(P15<>"","VERDE",IF(AND(H15<>"",TODAY()>H15),"ROJO",IF(COUNT(I15:P15)=0,"GRIS","AMARILLO")))) -> GRIS | U15: =IF(COUNT(I15:P15)=0,"",TODAY()-MAX(I15:P15))
A16: PB2020260202 | Q16: =IF(P16<>"","Llega bodega",IF(O16<>"","Llega puerto MX",IF(N16<>"","Sale puerto origen",IF(M16<>"","Producción OK",IF(L16<>"","Anticipo",IF(K16<>"","Info empaque",IF(J16<>"","Aprobar",IF(I16<>"","Cotizar","Sin iniciar")))))))) -> Sin iniciar | R16: =IF(A16="","",IF(P16<>"","COMPLETA",IF(N16<>"","EN TRÁNSITO",IF(M16<>"","EN PRODUCCIÓN",IF(L16<>"","PAGADA / EN ESPERA","EN GESTIÓN"))))) -> EN GESTIÓN | S16: =COUNT(I16:P16)/8 -> 0 | T16: =IF(A16="","",IF(P16<>"","VERDE",IF(AND(H16<>"",TODAY()>H16),"ROJO",IF(COUNT(I16:P16)=0,"GRIS","AMARILLO")))) -> GRIS | U16: =IF(COUNT(I16:P16)=0,"",TODAY()-MAX(I16:P16))
Q17: =IF(P17<>"","Llega bodega",IF(O17<>"","Llega puerto MX",IF(N17<>"","Sale puerto origen",IF(M17<>"","Producción OK",IF(L17<>"","Anticipo",IF(K17<>"","Info empaque",IF(J17<>"","Aprobar",IF(I17<>"","Cotizar","Sin iniciar")))))))) -> Sin iniciar | R17: =IF(A17="","",IF(P17<>"","COMPLETA",IF(N17<>"","EN TRÁNSITO",IF(M17<>"","EN PRODUCCIÓN",IF(L17<>"","PAGADA / EN ESPERA","EN GESTIÓN"))))) | S17: =COUNT(I17:P17)/8 -> 0 | T17: =IF(A17="","",IF(P17<>"","VERDE",IF(AND(H17<>"",TODAY()>H17),"ROJO",IF(COUNT(I17:P17)=0,"GRIS","AMARILLO")))) | U17: =IF(COUNT(I17:P17)=0,"",TODAY()-MAX(I17:P17))
Q18: =IF(P18<>"","Llega bodega",IF(O18<>"","Llega puerto MX",IF(N18<>"","Sale puerto origen",IF(M18<>"","Producción OK",IF(L18<>"","Anticipo",IF(K18<>"","Info empaque",IF(J18<>"","Aprobar",IF(I18<>"","Cotizar","Sin iniciar")))))))) -> Sin iniciar | R18: =IF(A18="","",IF(P18<>"","COMPLETA",IF(N18<>"","EN TRÁNSITO",IF(M18<>"","EN PRODUCCIÓN",IF(L18<>"","PAGADA / EN ESPERA","EN GESTIÓN"))))) | S18: =COUNT(I18:P18)/8 -> 0 | T18: =IF(A18="","",IF(P18<>"","VERDE",IF(AND(H18<>"",TODAY()>H18),"ROJO",IF(COUNT(I18:P18)=0,"GRIS","AMARILLO")))) | U18: =IF(COUNT(I18:P18)=0,"",TODAY()-MAX(I18:P18))
Q19: =IF(P19<>"","Llega bodega",IF(O19<>"","Llega puerto MX",IF(N19<>"","Sale puerto origen",IF(M19<>"","Producción OK",IF(L19<>"","Anticipo",IF(K19<>"","Info empaque",IF(J19<>"","Aprobar",IF(I19<>"","Cotizar","Sin iniciar")))))))) -> Sin iniciar | R19: =IF(A19="","",IF(P19<>"","COMPLETA",IF(N19<>"","EN TRÁNSITO",IF(M19<>"","EN PRODUCCIÓN",IF(L19<>"","PAGADA / EN ESPERA","EN GESTIÓN"))))) | S19: =COUNT(I19:P19)/8 -> 0 | T19: =IF(A19="","",IF(P19<>"","VERDE",IF(AND(H19<>"",TODAY()>H19),"ROJO",IF(COUNT(I19:P19)=0,"GRIS","AMARILLO")))) | U19: =IF(COUNT(I19:P19)=0,"",TODAY()-MAX(I19:P19))
Q20: =IF(P20<>"","Llega bodega",IF(O20<>"","Llega puerto MX",IF(N20<>"","Sale puerto origen",IF(M20<>"","Producción OK",IF(L20<>"","Anticipo",IF(K20<>"","Info empaque",IF(J20<>"","Aprobar",IF(I20<>"","Cotizar","Sin iniciar")))))))) -> Sin iniciar | R20: =IF(A20="","",IF(P20<>"","COMPLETA",IF(N20<>"","EN TRÁNSITO",IF(M20<>"","EN PRODUCCIÓN",IF(L20<>"","PAGADA / EN ESPERA","EN GESTIÓN"))))) | S20: =COUNT(I20:P20)/8 -> 0 | T20: =IF(A20="","",IF(P20<>"","VERDE",IF(AND(H20<>"",TODAY()>H20),"ROJO",IF(COUNT(I20:P20)=0,"GRIS","AMARILLO")))) | U20: =IF(COUNT(I20:P20)=0,"",TODAY()-MAX(I20:P20))
Q21: =IF(P21<>"","Llega bodega",IF(O21<>"","Llega puerto MX",IF(N21<>"","Sale puerto origen",IF(M21<>"","Producción OK",IF(L21<>"","Anticipo",IF(K21<>"","Info empaque",IF(J21<>"","Aprobar",IF(I21<>"","Cotizar","Sin iniciar")))))))) -> Sin iniciar | R21: =IF(A21="","",IF(P21<>"","COMPLETA",IF(N21<>"","EN TRÁNSITO",IF(M21<>"","EN PRODUCCIÓN",IF(L21<>"","PAGADA / EN ESPERA","EN GESTIÓN"))))) | S21: =COUNT(I21:P21)/8 -> 0 | T21: =IF(A21="","",IF(P21<>"","VERDE",IF(AND(H21<>"",TODAY()>H21),"ROJO",IF(COUNT(I21:P21)=0,"GRIS","AMARILLO")))) | U21: =IF(COUNT(I21:P21)=0,"",TODAY()-MAX(I21:P21))
I22: cvsdffvcdsvds | Q22: =IF(P22<>"","Llega bodega",IF(O22<>"","Llega puerto MX",IF(N22<>"","Sale puerto origen",IF(M22<>"","Producción OK",IF(L22<>"","Anticipo",IF(K22<>"","Info empaque",IF(J22<>"","Aprobar",IF(I22<>"","Cotizar","Sin iniciar")))))))) -> Cotizar | R22: =IF(A22="","",IF(P22<>"","COMPLETA",IF(N22<>"","EN TRÁNSITO",IF(M22<>"","EN PRODUCCIÓN",IF(L22<>"","PAGADA / EN ESPERA","EN GESTIÓN"))))) | S22: =COUNT(I22:P22)/8 -> 0 | T22: =IF(A22="","",IF(P22<>"","VERDE",IF(AND(H22<>"",TODAY()>H22),"ROJO",IF(COUNT(I22:P22)=0,"GRIS","AMARILLO")))) | U22: =IF(COUNT(I22:P22)=0,"",TODAY()-MAX(I22:P22))
I23: dsvdsvojsd | Q23: =IF(P23<>"","Llega bodega",IF(O23<>"","Llega puerto MX",IF(N23<>"","Sale puerto origen",IF(M23<>"","Producción OK",IF(L23<>"","Anticipo",IF(K23<>"","Info empaque",IF(J23<>"","Aprobar",IF(I23<>"","Cotizar","Sin iniciar")))))))) -> Cotizar | R23: =IF(A23="","",IF(P23<>"","COMPLETA",IF(N23<>"","EN TRÁNSITO",IF(M23<>"","EN PRODUCCIÓN",IF(L23<>"","PAGADA / EN ESPERA","EN GESTIÓN"))))) | S23: =COUNT(I23:P23)/8 -> 0 | T23: =IF(A23="","",IF(P23<>"","VERDE",IF(AND(H23<>"",TODAY()>H23),"ROJO",IF(COUNT(I23:P23)=0,"GRIS","AMARILLO")))) | U23: =IF(COUNT(I23:P23)=0,"",TODAY()-MAX(I23:P23))
I24: s | Q24: =IF(P24<>"","Llega bodega",IF(O24<>"","Llega puerto MX",IF(N24<>"","Sale puerto origen",IF(M24<>"","Producción OK",IF(L24<>"","Anticipo",IF(K24<>"","Info empaque",IF(J24<>"","Aprobar",IF(I24<>"","Cotizar","Sin iniciar")))))))) -> Cotizar | R24: =IF(A24="","",IF(P24<>"","COMPLETA",IF(N24<>"","EN TRÁNSITO",IF(M24<>"","EN PRODUCCIÓN",IF(L24<>"","PAGADA / EN ESPERA","EN GESTIÓN"))))) | S24: =COUNT(I24:P24)/8 -> 0 | T24: =IF(A24="","",IF(P24<>"","VERDE",IF(AND(H24<>"",TODAY()>H24),"ROJO",IF(COUNT(I24:P24)=0,"GRIS","AMARILLO")))) | U24: =IF(COUNT(I24:P24)=0,"",TODAY()-MAX(I24:P24))
Q25: =IF(P25<>"","Llega bodega",IF(O25<>"","Llega puerto MX",IF(N25<>"","Sale puerto origen",IF(M25<>"","Producción OK",IF(L25<>"","Anticipo",IF(K25<>"","Info empaque",IF(J25<>"","Aprobar",IF(I25<>"","Cotizar","Sin iniciar")))))))) -> Sin iniciar | R25: =IF(A25="","",IF(P25<>"","COMPLETA",IF(N25<>"","EN TRÁNSITO",IF(M25<>"","EN PRODUCCIÓN",IF(L25<>"","PAGADA / EN ESPERA","EN GESTIÓN"))))) | S25: =COUNT(I25:P25)/8 -> 0 | T25: =IF(A25="","",IF(P25<>"","VERDE",IF(AND(H25<>"",TODAY()>H25),"ROJO",IF(COUNT(I25:P25)=0,"GRIS","AMARILLO")))) | U25: =IF(COUNT(I25:P25)=0,"",TODAY()-MAX(I25:P25))
Q26: =IF(P26<>"","Llega bodega",IF(O26<>"","Llega puerto MX",IF(N26<>"","Sale puerto origen",IF(M26<>"","Producción OK",IF(L26<>"","Anticipo",IF(K26<>"","Info empaque",IF(J26<>"","Aprobar",IF(I26<>"","Cotizar","Sin iniciar")))))))) -> Sin iniciar | R26: =IF(A26="","",IF(P26<>"","COMPLETA",IF(N26<>"","EN TRÁNSITO",IF(M26<>"","EN PRODUCCIÓN",IF(L26<>"","PAGADA / EN ESPERA","EN GESTIÓN"))))) | S26: =COUNT(I26:P26)/8 -> 0 | T26: =IF(A26="","",IF(P26<>"","VERDE",IF(AND(H26<>"",TODAY()>H26),"ROJO",IF(COUNT(I26:P26)=0,"GRIS","AMARILLO")))) | U26: =IF(COUNT(I26:P26)=0,"",TODAY()-MAX(I26:P26))
Q27: =IF(P27<>"","Llega bodega",IF(O27<>"","Llega puerto MX",IF(N27<>"","Sale puerto origen",IF(M27<>"","Producción OK",IF(L27<>"","Anticipo",IF(K27<>"","Info empaque",IF(J27<>"","Aprobar",IF(I27<>"","Cotizar","Sin iniciar")))))))) -> Sin iniciar | R27: =IF(A27="","",IF(P27<>"","COMPLETA",IF(N27<>"","EN TRÁNSITO",IF(M27<>"","EN PRODUCCIÓN",IF(L27<>"","PAGADA / EN ESPERA","EN GESTIÓN"))))) | S27: =COUNT(I27:P27)/8 -> 0 | T27: =IF(A27="","",IF(P27<>"","VERDE",IF(AND(H27<>"",TODAY()>H27),"ROJO",IF(COUNT(I27:P27)=0,"GRIS","AMARILLO")))) | U27: =IF(COUNT(I27:P27)=0,"",TODAY()-MAX(I27:P27))
Q28: =IF(P28<>"","Llega bodega",IF(O28<>"","Llega puerto MX",IF(N28<>"","Sale puerto origen",IF(M28<>"","Producción OK",IF(L28<>"","Anticipo",IF(K28<>"","Info empaque",IF(J28<>"","Aprobar",IF(I28<>"","Cotizar","Sin iniciar")))))))) -> Sin iniciar | R28: =IF(A28="","",IF(P28<>"","COMPLETA",IF(N28<>"","EN TRÁNSITO",IF(M28<>"","EN PRODUCCIÓN",IF(L28<>"","PAGADA / EN ESPERA","EN GESTIÓN"))))) | S28: =COUNT(I28:P28)/8 -> 0 | T28: =IF(A28="","",IF(P28<>"","VERDE",IF(AND(H28<>"",TODAY()>H28),"ROJO",IF(COUNT(I28:P28)=0,"GRIS","AMARILLO")))) | U28: =IF(COUNT(I28:P28)=0,"",TODAY()-MAX(I28:P28))
Q29: =IF(P29<>"","Llega bodega",IF(O29<>"","Llega puerto MX",IF(N29<>"","Sale puerto origen",IF(M29<>"","Producción OK",IF(L29<>"","Anticipo",IF(K29<>"","Info empaque",IF(J29<>"","Aprobar",IF(I29<>"","Cotizar","Sin iniciar")))))))) -> Sin iniciar | R29: =IF(A29="","",IF(P29<>"","COMPLETA",IF(N29<>"","EN TRÁNSITO",IF(M29<>"","EN PRODUCCIÓN",IF(L29<>"","PAGADA / EN ESPERA","EN GESTIÓN"))))) | S29: =COUNT(I29:P29)/8 -> 0 | T29: =IF(A29="","",IF(P29<>"","VERDE",IF(AND(H29<>"",TODAY()>H29),"ROJO",IF(COUNT(I29:P29)=0,"GRIS","AMARILLO")))) | U29: =IF(COUNT(I29:P29)=0,"",TODAY()-MAX(I29:P29))
Q30: =IF(P30<>"","Llega bodega",IF(O30<>"","Llega puerto MX",IF(N30<>"","Sale puerto origen",IF(M30<>"","Producción OK",IF(L30<>"","Anticipo",IF(K30<>"","Info empaque",IF(J30<>"","Aprobar",IF(I30<>"","Cotizar","Sin iniciar")))))))) -> Sin iniciar | R30: =IF(A30="","",IF(P30<>"","COMPLETA",IF(N30<>"","EN TRÁNSITO",IF(M30<>"","EN PRODUCCIÓN",IF(L30<>"","PAGADA / EN ESPERA","EN GESTIÓN"))))) | S30: =COUNT(I30:P30)/8 -> 0 | T30: =IF(A30="","",IF(P30<>"","VERDE",IF(AND(H30<>"",TODAY()>H30),"ROJO",IF(COUNT(I30:P30)=0,"GRIS","AMARILLO")))) | U30: =IF(COUNT(I30:P30)=0,"",TODAY()-MAX(I30:P30))
Q31: =IF(P31<>"","Llega bodega",IF(O31<>"","Llega puerto MX",IF(N31<>"","Sale puerto origen",IF(M31<>"","Producción OK",IF(L31<>"","Anticipo",IF(K31<>"","Info empaque",IF(J31<>"","Aprobar",IF(I31<>"","Cotizar","Sin iniciar")))))))) -> Sin iniciar | R31: =IF(A31="","",IF(P31<>"","COMPLETA",IF(N31<>"","EN TRÁNSITO",IF(M31<>"","EN PRODUCCIÓN",IF(L31<>"","PAGADA / EN ESPERA","EN GESTIÓN"))))) | S31: =COUNT(I31:P31)/8 -> 0 | T31: =IF(A31="","",IF(P31<>"","VERDE",IF(AND(H31<>"",TODAY()>H31),"ROJO",IF(COUNT(I31:P31)=0,"GRIS","AMARILLO")))) | U31: =IF(COUNT(I31:P31)=0,"",TODAY()-MAX(I31:P31))
Q32: =IF(P32<>"","Llega bodega",IF(O32<>"","Llega puerto MX",IF(N32<>"","Sale puerto origen",IF(M32<>"","Producción OK",IF(L32<>"","Anticipo",IF(K32<>"","Info empaque",IF(J32<>"","Aprobar",IF(I32<>"","Cotizar","Sin iniciar")))))))) -> Sin iniciar | R32: =IF(A32="","",IF(P32<>"","COMPLETA",IF(N32<>"","EN TRÁNSITO",IF(M32<>"","EN PRODUCCIÓN",IF(L32<>"","PAGADA / EN ESPERA","EN GESTIÓN"))))) | S32: =COUNT(I32:P32)/8 -> 0 | T32: =IF(A32="","",IF(P32<>"","VERDE",IF(AND(H32<>"",TODAY()>H32),"ROJO",IF(COUNT(I32:P32)=0,"GRIS","AMARILLO")))) | U32: =IF(COUNT(I32:P32)=0,"",TODAY()-MAX(I32:P32))
Q33: =IF(P33<>"","Llega bodega",IF(O33<>"","Llega puerto MX",IF(N33<>"","Sale puerto origen",IF(M33<>"","Producción OK",IF(L33<>"","Anticipo",IF(K33<>"","Info empaque",IF(J33<>"","Aprobar",IF(I33<>"","Cotizar","Sin iniciar")))))))) -> Sin iniciar | R33: =IF(A33="","",IF(P33<>"","COMPLETA",IF(N33<>"","EN TRÁNSITO",IF(M33<>"","EN PRODUCCIÓN",IF(L33<>"","PAGADA / EN ESPERA","EN GESTIÓN"))))) | S33: =COUNT(I33:P33)/8 -> 0 | T33: =IF(A33="","",IF(P33<>"","VERDE",IF(AND(H33<>"",TODAY()>H33),"ROJO",IF(COUNT(I33:P33)=0,"GRIS","AMARILLO")))) | U33: =IF(COUNT(I33:P33)=0,"",TODAY()-MAX(I33:P33))
Q34: =IF(P34<>"","Llega bodega",IF(O34<>"","Llega puerto MX",IF(N34<>"","Sale puerto origen",IF(M34<>"","Producción OK",IF(L34<>"","Anticipo",IF(K34<>"","Info empaque",IF(J34<>"","Aprobar",IF(I34<>"","Cotizar","Sin iniciar")))))))) -> Sin iniciar | R34: =IF(A34="","",IF(P34<>"","COMPLETA",IF(N34<>"","EN TRÁNSITO",IF(M34<>"","EN PRODUCCIÓN",IF(L34<>"","PAGADA / EN ESPERA","EN GESTIÓN"))))) | S34: =COUNT(I34:P34)/8 -> 0 | T34: =IF(A34="","",IF(P34<>"","VERDE",IF(AND(H34<>"",TODAY()>H34),"ROJO",IF(COUNT(I34:P34)=0,"GRIS","AMARILLO")))) | U34: =IF(COUNT(I34:P34)=0,"",TODAY()-MAX(I34:P34))
Q35: =IF(P35<>"","Llega bodega",IF(O35<>"","Llega puerto MX",IF(N35<>"","Sale puerto origen",IF(M35<>"","Producción OK",IF(L35<>"","Anticipo",IF(K35<>"","Info empaque",IF(J35<>"","Aprobar",IF(I35<>"","Cotizar","Sin iniciar")))))))) -> Sin iniciar | R35: =IF(A35="","",IF(P35<>"","COMPLETA",IF(N35<>"","EN TRÁNSITO",IF(M35<>"","EN PRODUCCIÓN",IF(L35<>"","PAGADA / EN ESPERA","EN GESTIÓN"))))) | S35: =COUNT(I35:P35)/8 -> 0 | T35: =IF(A35="","",IF(P35<>"","VERDE",IF(AND(H35<>"",TODAY()>H35),"ROJO",IF(COUNT(I35:P35)=0,"GRIS","AMARILLO")))) | U35: =IF(COUNT(I35:P35)=0,"",TODAY()-MAX(I35:P35))
Q36: =IF(P36<>"","Llega bodega",IF(O36<>"","Llega puerto MX",IF(N36<>"","Sale puerto origen",IF(M36<>"","Producción OK",IF(L36<>"","Anticipo",IF(K36<>"","Info empaque",IF(J36<>"","Aprobar",IF(I36<>"","Cotizar","Sin iniciar")))))))) -> Sin iniciar | R36: =IF(A36="","",IF(P36<>"","COMPLETA",IF(N36<>"","EN TRÁNSITO",IF(M36<>"","EN PRODUCCIÓN",IF(L36<>"","PAGADA / EN ESPERA","EN GESTIÓN"))))) | S36: =COUNT(I36:P36)/8 -> 0 | T36: =IF(A36="","",IF(P36<>"","VERDE",IF(AND(H36<>"",TODAY()>H36),"ROJO",IF(COUNT(I36:P36)=0,"GRIS","AMARILLO")))) | U36: =IF(COUNT(I36:P36)=0,"",TODAY()-MAX(I36:P36))
... Q40: =IF(P40<>"","Llega bodega",IF(O40<>"","Llega puerto MX",IF(N40<>"","Sale puerto origen",IF(M40<>"","Producción OK",IF(L40<>"","Anticipo",IF(K40<>"","Info empaque",IF(J40<>"","Aprobar",IF(I40<>"","Cotizar","Sin iniciar")))))))) -> Sin iniciar | R40: =IF(A40="","",IF(P40<>"","COMPLETA",IF(N40<>"","EN TRÁNSITO",IF(M40<>"","EN PRODUCCIÓN",IF(L40<>"","PAGADA / EN ESPERA","EN GESTIÓN"))))) | S40: =COUNT(I40:P40)/8 -> 0 | T40: =IF(A40="","",IF(P40<>"","VERDE",IF(AND(H40<>"",TODAY()>H40),"ROJO",IF(COUNT(I40:P40)=0,"GRIS","AMARILLO")))) | U40: =IF(COUNT(I40:P40)=0,"",TODAY()-MAX(I40:P40))
A42: Cómo funciona el semáforo por proceso: | B42: Verde = hito completado | Amarillo = siguiente hito a ejecutar | Gris = hito futuro | Rojo = la orden ya venció vs ETA Bodega
A43: Tip: | B43: Captura fechas reales en los hitos H:O. El dashboard se actualiza solo.

Sheet CANPY LINA
A1: GEESNA | Control de Órdenes de Contenedor - LINA
A3: Proveedor | B3: LINA | D3: Contacto | G3: País | H3: China | J3: Responsable
A4: Órdenes | D4: Monto total | G4: Completas | J4: Activas | M4: En rojo | P4: % avance prom. | S4: Próx. ETA bodega
A5: =COUNTIF(A11:A40,"<>") -> 11 | D5: =SUM(E11:E40) -> 100792.7 | G5: =COUNTIF(R11:R40,"COMPLETA") -> 0 | J5: =COUNTIFS(R11:R40,"<>COMPLETA",A11:A40,"<>") -> 11 | M5: =COUNTIF(T11:T40,"ROJO") -> 0 | P5: =IFERROR(AVERAGE(S11:S40),0) -> 0 | S5: =IFERROR(MINIFS(G11:G40,R11:R40,"<>COMPLETA",G11:G40,">0"),0) -> 0
A8: Semáforo proveedor | B8: =IF(J5>0,"ROJO",IF(H5>0,"AMARILLO","VERDE")) -> ROJO | D8: Siguiente acción | E8: =IF(B8="ROJO","Escalar órdenes vencidas",IF(B8="AMARILLO","Monitorear órdenes activas","Operación estable")) -> Escalar órdenes vencidas
A10: Orden ID | B10: Producto / SKU | C10: Contenedor | D10: Responsable | E10: Monto Orden | F10: ETA Puerto MX | G10: ETA Bodega | H10: Cotizar | I10: Aprobar | J10: Info empaque | K10: Anticipo | L10: Producción OK | M10: Sale puerto origen | N10: Llega puerto MX | O10: Llega bodega | P10: Etapa actual | Q10: Estado orden | R10: % avance | S10: Semáforo | T10: Días sin movimiento | U10: Notas
A11: PXK-25L1117-1 | B11: 3x3 W R B | C11: TCLU9134729 | E11: 13590 | H11: done | I11: done | J11: done | K11: done | L11: done | M11: 46023 | N11: 46037 | O11: 46052 | P11: =IF(O11<>"","Llega bodega",IF(N11<>"","Llega puerto MX",IF(M11<>"","Sale puerto origen",IF(L11<>"","Producción OK",IF(K11<>"","Anticipo",IF(J11<>"","Info empaque",IF(I11<>"","Aprobar",IF(H11<>"","Cotizar","Sin iniciar")))))))) -> Llega bodega | Q11: =IF(A11="","",IF(O11<>"","COMPLETA",IF(M11<>"","EN TRÁNSITO",IF(L11<>"","EN PRODUCCIÓN",IF(K11<>"","PAGADA / EN ESPERA","EN GESTIÓN"))))) -> COMPLETA | R11: =COUNT(H11:O11)/8 -> 0.375 | S11: =IF(A11="","",IF(O11<>"","VERDE",IF(AND(G11<>"",TODAY()>G11),"ROJO",IF(COUNT(H11:O11)=0,"GRIS","AMARILLO")))) -> VERDE | T11: =IF(COUNT(H11:O11)=0,"",TODAY()-MAX(H11:O11)) -> 120
A12: PXK-25L1117-2 | B12: 2x2 W R B | C12: MSNU7986327 | E12: 12240 | H12: done | I12: done | J12: done | K12: done | L12: done | P12: =IF(O12<>"","Llega bodega",IF(N12<>"","Llega puerto MX",IF(M12<>"","Sale puerto origen",IF(L12<>"","Producción OK",IF(K12<>"","Anticipo",IF(J12<>"","Info empaque",IF(I12<>"","Aprobar",IF(H12<>"","Cotizar","Sin iniciar")))))))) -> Producción OK | Q12: =IF(A12="","",IF(O12<>"","COMPLETA",IF(M12<>"","EN TRÁNSITO",IF(L12<>"","EN PRODUCCIÓN",IF(K12<>"","PAGADA / EN ESPERA","EN GESTIÓN"))))) -> EN PRODUCCIÓN | R12: =COUNT(H12:O12)/8 -> 0 | S12: =IF(A12="","",IF(O12<>"","VERDE",IF(AND(G12<>"",TODAY()>G12),"ROJO",IF(COUNT(H12:O12)=0,"GRIS","AMARILLO")))) -> GRIS | T12: =IF(COUNT(H12:O12)=0,"",TODAY()-MAX(H12:O12))
A13: PXK-25L1117-3 | B13: Cubierta / Laterales | C13: TIIU4416290 | E13: 21276.4 | H13: done | I13: done | J13: done | K13: done | L13: done | P13: =IF(O13<>"","Llega bodega",IF(N13<>"","Llega puerto MX",IF(M13<>"","Sale puerto origen",IF(L13<>"","Producción OK",IF(K13<>"","Anticipo",IF(J13<>"","Info empaque",IF(I13<>"","Aprobar",IF(H13<>"","Cotizar","Sin iniciar")))))))) -> Producción OK | Q13: =IF(A13="","",IF(O13<>"","COMPLETA",IF(M13<>"","EN TRÁNSITO",IF(L13<>"","EN PRODUCCIÓN",IF(K13<>"","PAGADA / EN ESPERA","EN GESTIÓN"))))) -> EN PRODUCCIÓN | R13: =COUNT(H13:O13)/8 -> 0 | S13: =IF(A13="","",IF(O13<>"","VERDE",IF(AND(G13<>"",TODAY()>G13),"ROJO",IF(COUNT(H13:O13)=0,"GRIS","AMARILLO")))) -> GRIS | T13: =IF(COUNT(H13:O13)=0,"",TODAY()-MAX(H13:O13))
A14: PXK-25L1117-4 | B14: 3x4.5 W R B | C14: MSBU5256338 | E14: 14693.8 | H14: done | I14: done | J14: done | K14: done | P14: =IF(O14<>"","Llega bodega",IF(N14<>"","Llega puerto MX",IF(M14<>"","Sale puerto origen",IF(L14<>"","Producción OK",IF(K14<>"","Anticipo",IF(J14<>"","Info empaque",IF(I14<>"","Aprobar",IF(H14<>"","Cotizar","Sin iniciar")))))))) -> Anticipo | Q14: =IF(A14="","",IF(O14<>"","COMPLETA",IF(M14<>"","EN TRÁNSITO",IF(L14<>"","EN PRODUCCIÓN",IF(K14<>"","PAGADA / EN ESPERA","EN GESTIÓN"))))) -> PAGADA / EN ESPERA | R14: =COUNT(H14:O14)/8 -> 0 | S14: =IF(A14="","",IF(O14<>"","VERDE",IF(AND(G14<>"",TODAY()>G14),"ROJO",IF(COUNT(H14:O14)=0,"GRIS","AMARILLO")))) -> GRIS | T14: =IF(COUNT(H14:O14)=0,"",TODAY()-MAX(H14:O14))
A15: PXK-25L1117-5 | B15: 3x6 W R B | C15: MEDU4653752 | E15: 14031 | H15: done | I15: done | J15: done | K15: done | P15: =IF(O15<>"","Llega bodega",IF(N15<>"","Llega puerto MX",IF(M15<>"","Sale puerto origen",IF(L15<>"","Producción OK",IF(K15<>"","Anticipo",IF(J15<>"","Info empaque",IF(I15<>"","Aprobar",IF(H15<>"","Cotizar","Sin iniciar")))))))) -> Anticipo | Q15: =IF(A15="","",IF(O15<>"","COMPLETA",IF(M15<>"","EN TRÁNSITO",IF(L15<>"","EN PRODUCCIÓN",IF(K15<>"","PAGADA / EN ESPERA","EN GESTIÓN"))))) -> PAGADA / EN ESPERA | R15: =COUNT(H15:O15)/8 -> 0 | S15: =IF(A15="","",IF(O15<>"","VERDE",IF(AND(G15<>"",TODAY()>G15),"ROJO",IF(COUNT(H15:O15)=0,"GRIS","AMARILLO")))) -> GRIS | T15: =IF(COUNT(H15:O15)=0,"",TODAY()-MAX(H15:O15))
A16: PXK-25L1117-6 | B16: 2x3 W R B | C16: MSNU5184549 | E16: 11977.8 | H16: done | I16: done | J16: done | P16: =IF(O16<>"","Llega bodega",IF(N16<>"","Llega puerto MX",IF(M16<>"","Sale puerto origen",IF(L16<>"","Producción OK",IF(K16<>"","Anticipo",IF(J16<>"","Info empaque",IF(I16<>"","Aprobar",IF(H16<>"","Cotizar","Sin iniciar")))))))) -> Info empaque | Q16: =IF(A16="","",IF(O16<>"","COMPLETA",IF(M16<>"","EN TRÁNSITO",IF(L16<>"","EN PRODUCCIÓN",IF(K16<>"","PAGADA / EN ESPERA","EN GESTIÓN"))))) -> EN GESTIÓN | R16: =COUNT(H16:O16)/8 -> 0 | S16: =IF(A16="","",IF(O16<>"","VERDE",IF(AND(G16<>"",TODAY()>G16),"ROJO",IF(COUNT(H16:O16)=0,"GRIS","AMARILLO")))) -> GRIS | T16: =IF(COUNT(H16:O16)=0,"",TODAY()-MAX(H16:O16))
A17: PXK-25L1117-7 | B17: residuales | C17: MSMU6514615 | E17: 12983.7 | H17: done | I17: done | P17: =IF(O17<>"","Llega bodega",IF(N17<>"","Llega puerto MX",IF(M17<>"","Sale puerto origen",IF(L17<>"","Producción OK",IF(K17<>"","Anticipo",IF(J17<>"","Info empaque",IF(I17<>"","Aprobar",IF(H17<>"","Cotizar","Sin iniciar")))))))) -> Aprobar | Q17: =IF(A17="","",IF(O17<>"","COMPLETA",IF(M17<>"","EN TRÁNSITO",IF(L17<>"","EN PRODUCCIÓN",IF(K17<>"","PAGADA / EN ESPERA","EN GESTIÓN"))))) -> EN GESTIÓN | R17: =COUNT(H17:O17)/8 -> 0 | S17: =IF(A17="","",IF(O17<>"","VERDE",IF(AND(G17<>"",TODAY()>G17),"ROJO",IF(COUNT(H17:O17)=0,"GRIS","AMARILLO")))) -> GRIS | T17: =IF(COUNT(H17:O17)=0,"",TODAY()-MAX(H17:O17))
A18: PXK-26L0108(SG-08) | B18: 3x3 W R B | P18: =IF(O18<>"","Llega bodega",IF(N18<>"","Llega puerto MX",IF(M18<>"","Sale puerto origen",IF(L18<>"","Producción OK",IF(K18<>"","Anticipo",IF(J18<>"","Info empaque",IF(I18<>"","Aprobar",IF(H18<>"","Cotizar","Sin iniciar")))))))) -> Sin iniciar | Q18: =IF(A18="","",IF(O18<>"","COMPLETA",IF(M18<>"","EN TRÁNSITO",IF(L18<>"","EN PRODUCCIÓN",IF(K18<>"","PAGADA / EN ESPERA","EN GESTIÓN"))))) -> EN GESTIÓN | R18: =COUNT(H18:O18)/8 -> 0 | S18: =IF(A18="","",IF(O18<>"","VERDE",IF(AND(G18<>"",TODAY()>G18),"ROJO",IF(COUNT(H18:O18)=0,"GRIS","AMARILLO")))) -> GRIS | T18: =IF(COUNT(H18:O18)=0,"",TODAY()-MAX(H18:O18))
A19: PXK-26L0112(SG-09) | P19: =IF(O19<>"","Llega bodega",IF(N19<>"","Llega puerto MX",IF(M19<>"","Sale puerto origen",IF(L19<>"","Producción OK",IF(K19<>"","Anticipo",IF(J19<>"","Info empaque",IF(I19<>"","Aprobar",IF(H19<>"","Cotizar","Sin iniciar")))))))) -> Sin iniciar | Q19: =IF(A19="","",IF(O19<>"","COMPLETA",IF(M19<>"","EN TRÁNSITO",IF(L19<>"","EN PRODUCCIÓN",IF(K19<>"","PAGADA / EN ESPERA","EN GESTIÓN"))))) -> EN GESTIÓN | R19: =COUNT(H19:O19)/8 -> 0 | S19: =IF(A19="","",IF(O19<>"","VERDE",IF(AND(G19<>"",TODAY()>G19),"ROJO",IF(COUNT(H19:O19)=0,"GRIS","AMARILLO")))) -> GRIS | T19: =IF(COUNT(H19:O19)=0,"",TODAY()-MAX(H19:O19))
A20: SG-10 | P20: =IF(O20<>"","Llega bodega",IF(N20<>"","Llega puerto MX",IF(M20<>"","Sale puerto origen",IF(L20<>"","Producción OK",IF(K20<>"","Anticipo",IF(J20<>"","Info empaque",IF(I20<>"","Aprobar",IF(H20<>"","Cotizar","Sin iniciar")))))))) -> Sin iniciar | Q20: =IF(A20="","",IF(O20<>"","COMPLETA",IF(M20<>"","EN TRÁNSITO",IF(L20<>"","EN PRODUCCIÓN",IF(K20<>"","PAGADA / EN ESPERA","EN GESTIÓN"))))) -> EN GESTIÓN | R20: =COUNT(H20:O20)/8 -> 0 | S20: =IF(A20="","",IF(O20<>"","VERDE",IF(AND(G20<>"",TODAY()>G20),"ROJO",IF(COUNT(H20:O20)=0,"GRIS","AMARILLO")))) -> GRIS | T20: =IF(COUNT(H20:O20)=0,"",TODAY()-MAX(H20:O20))
A21: SG-11 | P21: =IF(O21<>"","Llega bodega",IF(N21<>"","Llega puerto MX",IF(M21<>"","Sale puerto origen",IF(L21<>"","Producción OK",IF(K21<>"","Anticipo",IF(J21<>"","Info empaque",IF(I21<>"","Aprobar",IF(H21<>"","Cotizar","Sin iniciar")))))))) -> Sin iniciar | Q21: =IF(A21="","",IF(O21<>"","COMPLETA",IF(M21<>"","EN TRÁNSITO",IF(L21<>"","EN PRODUCCIÓN",IF(K21<>"","PAGADA / EN ESPERA","EN GESTIÓN"))))) -> EN GESTIÓN | R21: =COUNT(H21:O21)/8 -> 0 | S21: =IF(A21="","",IF(O21<>"","VERDE",IF(AND(G21<>"",TODAY()>G21),"ROJO",IF(COUNT(H21:O21)=0,"GRIS","AMARILLO")))) -> GRIS | T21: =IF(COUNT(H21:O21)=0,"",TODAY()-MAX(H21:O21))
P22: =IF(O22<>"","Llega bodega",IF(N22<>"","Llega puerto MX",IF(M22<>"","Sale puerto origen",IF(L22<>"","Producción OK",IF(K22<>"","Anticipo",IF(J22<>"","Info empaque",IF(I22<>"","Aprobar",IF(H22<>"","Cotizar","Sin iniciar")))))))) -> Sin iniciar | Q22: =IF(A22="","",IF(O22<>"","COMPLETA",IF(M22<>"","EN TRÁNSITO",IF(L22<>"","EN PRODUCCIÓN",IF(K22<>"","PAGADA / EN ESPERA","EN GESTIÓN"))))) | R22: =COUNT(H22:O22)/8 -> 0 | S22: =IF(A22="","",IF(O22<>"","VERDE",IF(AND(G22<>"",TODAY()>G22),"ROJO",IF(COUNT(H22:O22)=0,"GRIS","AMARILLO")))) | T22: =IF(COUNT(H22:O22)=0,"",TODAY()-MAX(H22:O22))
P23: =IF(O23<>"","Llega bodega",IF(N23<>"","Llega puerto MX",IF(M23<>"","Sale puerto origen",IF(L23<>"","Producción OK",IF(K23<>"","Anticipo",IF(J23<>"","Info empaque",IF(I23<>"","Aprobar",IF(H23<>"","Cotizar","Sin iniciar")))))))) -> Sin iniciar | Q23: =IF(A23="","",IF(O23<>"","COMPLETA",IF(M23<>"","EN TRÁNSITO",IF(L23<>"","EN PRODUCCIÓN",IF(K23<>"","PAGADA / EN ESPERA","EN GESTIÓN"))))) | R23: =COUNT(H23:O23)/8 -> 0 | S23: =IF(A23="","",IF(O23<>"","VERDE",IF(AND(G23<>"",TODAY()>G23),"ROJO",IF(COUNT(H23:O23)=0,"GRIS","AMARILLO")))) | T23: =IF(COUNT(H23:O23)=0,"",TODAY()-MAX(H23:O23))
P24: =IF(O24<>"","Llega bodega",IF(N24<>"","Llega puerto MX",IF(M24<>"","Sale puerto origen",IF(L24<>"","Producción OK",IF(K24<>"","Anticipo",IF(J24<>"","Info empaque",IF(I24<>"","Aprobar",IF(H24<>"","Cotizar","Sin iniciar")))))))) -> Sin iniciar | Q24: =IF(A24="","",IF(O24<>"","COMPLETA",IF(M24<>"","EN TRÁNSITO",IF(L24<>"","EN PRODUCCIÓN",IF(K24<>"","PAGADA / EN ESPERA","EN GESTIÓN"))))) | R24: =COUNT(H24:O24)/8 -> 0 | S24: =IF(A24="","",IF(O24<>"","VERDE",IF(AND(G24<>"",TODAY()>G24),"ROJO",IF(COUNT(H24:O24)=0,"GRIS","AMARILLO")))) | T24: =IF(COUNT(H24:O24)=0,"",TODAY()-MAX(H24:O24))
P25: =IF(O25<>"","Llega bodega",IF(N25<>"","Llega puerto MX",IF(M25<>"","Sale puerto origen",IF(L25<>"","Producción OK",IF(K25<>"","Anticipo",IF(J25<>"","Info empaque",IF(I25<>"","Aprobar",IF(H25<>"","Cotizar","Sin iniciar")))))))) -> Sin iniciar | Q25: =IF(A25="","",IF(O25<>"","COMPLETA",IF(M25<>"","EN TRÁNSITO",IF(L25<>"","EN PRODUCCIÓN",IF(K25<>"","PAGADA / EN ESPERA","EN GESTIÓN"))))) | R25: =COUNT(H25:O25)/8 -> 0 | S25: =IF(A25="","",IF(O25<>"","VERDE",IF(AND(G25<>"",TODAY()>G25),"ROJO",IF(COUNT(H25:O25)=0,"GRIS","AMARILLO")))) | T25: =IF(COUNT(H25:O25)=0,"",TODAY()-MAX(H25:O25))
P26: =IF(O26<>"","Llega bodega",IF(N26<>"","Llega puerto MX",IF(M26<>"","Sale puerto origen",IF(L26<>"","Producción OK",IF(K26<>"","Anticipo",IF(J26<>"","Info empaque",IF(I26<>"","Aprobar",IF(H26<>"","Cotizar","Sin iniciar")))))))) -> Sin iniciar | Q26: =IF(A26="","",IF(O26<>"","COMPLETA",IF(M26<>"","EN TRÁNSITO",IF(L26<>"","EN PRODUCCIÓN",IF(K26<>"","PAGADA / EN ESPERA","EN GESTIÓN"))))) | R26: =COUNT(H26:O26)/8 -> 0 | S26: =IF(A26="","",IF(O26<>"","VERDE",IF(AND(G26<>"",TODAY()>G26),"ROJO",IF(COUNT(H26:O26)=0,"GRIS","AMARILLO")))) | T26: =IF(COUNT(H26:O26)=0,"",TODAY()-MAX(H26:O26))
P27: =IF(O27<>"","Llega bodega",IF(N27<>"","Llega puerto MX",IF(M27<>"","Sale puerto origen",IF(L27<>"","Producción OK",IF(K27<>"","Anticipo",IF(J27<>"","Info empaque",IF(I27<>"","Aprobar",IF(H27<>"","Cotizar","Sin iniciar")))))))) -> Sin iniciar | Q27: =IF(A27="","",IF(O27<>"","COMPLETA",IF(M27<>"","EN TRÁNSITO",IF(L27<>"","EN PRODUCCIÓN",IF(K27<>"","PAGADA / EN ESPERA","EN GESTIÓN"))))) | R27: =COUNT(H27:O27)/8 -> 0 | S27: =IF(A27="","",IF(O27<>"","VERDE",IF(AND(G27<>"",TODAY()>G27),"ROJO",IF(COUNT(H27:O27)=0,"GRIS","AMARILLO")))) | T27: =IF(COUNT(H27:O27)=0,"",TODAY()-MAX(H27:O27))
P28: =IF(O28<>"","Llega bodega",IF(N28<>"","Llega puerto MX",IF(M28<>"","Sale puerto origen",IF(L28<>"","Producción OK",IF(K28<>"","Anticipo",IF(J28<>"","Info empaque",IF(I28<>"","Aprobar",IF(H28<>"","Cotizar","Sin iniciar")))))))) -> Sin iniciar | Q28: =IF(A28="","",IF(O28<>"","COMPLETA",IF(M28<>"","EN TRÁNSITO",IF(L28<>"","EN PRODUCCIÓN",IF(K28<>"","PAGADA / EN ESPERA","EN GESTIÓN"))))) | R28: =COUNT(H28:O28)/8 -> 0 | S28: =IF(A28="","",IF(O28<>"","VERDE",IF(AND(G28<>"",TODAY()>G28),"ROJO",IF(COUNT(H28:O28)=0,"GRIS","AMARILLO")))) | T28: =IF(COUNT(H28:O28)=0,"",TODAY()-MAX(H28:O28))
P29: =IF(O29<>"","Llega bodega",IF(N29<>"","Llega puerto MX",IF(M29<>"","Sale puerto origen",IF(L29<>"","Producción OK",IF(K29<>"","Anticipo",IF(J29<>"","Info empaque",IF(I29<>"","Aprobar",IF(H29<>"","Cotizar","Sin iniciar")))))))) -> Sin iniciar | Q29: =IF(A29="","",IF(O29<>"","COMPLETA",IF(M29<>"","EN TRÁNSITO",IF(L29<>"","EN PRODUCCIÓN",IF(K29<>"","PAGADA / EN ESPERA","EN GESTIÓN"))))) | R29: =COUNT(H29:O29)/8 -> 0 | S29: =IF(A29="","",IF(O29<>"","VERDE",IF(AND(G29<>"",TODAY()>G29),"ROJO",IF(COUNT(H29:O29)=0,"GRIS","AMARILLO")))) | T29: =IF(COUNT(H29:O29)=0,"",TODAY()-MAX(H29:O29))
P30: =IF(O30<>"","Llega bodega",IF(N30<>"","Llega puerto MX",IF(M30<>"","Sale puerto origen",IF(L30<>"","Producción OK",IF(K30<>"","Anticipo",IF(J30<>"","Info empaque",IF(I30<>"","Aprobar",IF(H30<>"","Cotizar","Sin iniciar")))))))) -> Sin iniciar | Q30: =IF(A30="","",IF(O30<>"","COMPLETA",IF(M30<>"","EN TRÁNSITO",IF(L30<>"","EN PRODUCCIÓN",IF(K30<>"","PAGADA / EN ESPERA","EN GESTIÓN"))))) | R30: =COUNT(H30:O30)/8 -> 0 | S30: =IF(A30="","",IF(O30<>"","VERDE",IF(AND(G30<>"",TODAY()>G30),"ROJO",IF(COUNT(H30:O30)=0,"GRIS","AMARILLO")))) | T30: =IF(COUNT(H30:O30)=0,"",TODAY()-MAX(H30:O30))
P31: =IF(O31<>"","Llega bodega",IF(N31<>"","Llega puerto MX",IF(M31<>"","Sale puerto origen",IF(L31<>"","Producción OK",IF(K31<>"","Anticipo",IF(J31<>"","Info empaque",IF(I31<>"","Aprobar",IF(H31<>"","Cotizar","Sin iniciar")))))))) -> Sin iniciar | Q31: =IF(A31="","",IF(O31<>"","COMPLETA",IF(M31<>"","EN TRÁNSITO",IF(L31<>"","EN PRODUCCIÓN",IF(K31<>"","PAGADA / EN ESPERA","EN GESTIÓN"))))) | R31: =COUNT(H31:O31)/8 -> 0 | S31: =IF(A31="","",IF(O31<>"","VERDE",IF(AND(G31<>"",TODAY()>G31),"ROJO",IF(COUNT(H31:O31)=0,"GRIS","AMARILLO")))) | T31: =IF(COUNT(H31:O31)=0,"",TODAY()-MAX(H31:O31))
P32: =IF(O32<>"","Llega bodega",IF(N32<>"","Llega puerto MX",IF(M32<>"","Sale puerto origen",IF(L32<>"","Producción OK",IF(K32<>"","Anticipo",IF(J32<>"","Info empaque",IF(I32<>"","Aprobar",IF(H32<>"","Cotizar","Sin iniciar")))))))) -> Sin iniciar | Q32: =IF(A32="","",IF(O32<>"","COMPLETA",IF(M32<>"","EN TRÁNSITO",IF(L32<>"","EN PRODUCCIÓN",IF(K32<>"","PAGADA / EN ESPERA","EN GESTIÓN"))))) | R32: =COUNT(H32:O32)/8 -> 0 | S32: =IF(A32="","",IF(O32<>"","VERDE",IF(AND(G32<>"",TODAY()>G32),"ROJO",IF(COUNT(H32:O32)=0,"GRIS","AMARILLO")))) | T32: =IF(COUNT(H32:O32)=0,"",TODAY()-MAX(H32:O32))
P33: =IF(O33<>"","Llega bodega",IF(N33<>"","Llega puerto MX",IF(M33<>"","Sale puerto origen",IF(L33<>"","Producción OK",IF(K33<>"","Anticipo",IF(J33<>"","Info empaque",IF(I33<>"","Aprobar",IF(H33<>"","Cotizar","Sin iniciar")))))))) -> Sin iniciar | Q33: =IF(A33="","",IF(O33<>"","COMPLETA",IF(M33<>"","EN TRÁNSITO",IF(L33<>"","EN PRODUCCIÓN",IF(K33<>"","PAGADA / EN ESPERA","EN GESTIÓN"))))) | R33: =COUNT(H33:O33)/8 -> 0 | S33: =IF(A33="","",IF(O33<>"","VERDE",IF(AND(G33<>"",TODAY()>G33),"ROJO",IF(COUNT(H33:O33)=0,"GRIS","AMARILLO")))) | T33: =IF(COUNT(H33:O33)=0,"",TODAY()-MAX(H33:O33))
... P40: =IF(O40<>"","Llega bodega",IF(N40<>"","Llega puerto MX",IF(M40<>"","Sale puerto origen",IF(L40<>"","Producción OK",IF(K40<>"","Anticipo",IF(J40<>"","Info empaque",IF(I40<>"","Aprobar",IF(H40<>"","Cotizar","Sin iniciar")))))))) -> Sin iniciar | Q40: =IF(A40="","",IF(O40<>"","COMPLETA",IF(M40<>"","EN TRÁNSITO",IF(L40<>"","EN PRODUCCIÓN",IF(K40<>"","PAGADA / EN ESPERA","EN GESTIÓN"))))) | R40: =COUNT(H40:O40)/8 -> 0 | S40: =IF(A40="","",IF(O40<>"","VERDE",IF(AND(G40<>"",TODAY()>G40),"ROJO",IF(COUNT(H40:O40)=0,"GRIS","AMARILLO")))) | T40: =IF(COUNT(H40:O40)=0,"",TODAY()-MAX(H40:O40))
A42: Cómo funciona el semáforo por proceso: | B42: Verde = hito completado | Amarillo = siguiente hito a ejecutar | Gris = hito futuro | Rojo = la orden ya venció vs ETA Bodega
A43: Tip: | B43: Captura fechas reales en los hitos H:O. El dashboard se actualiza solo.

Sheet Prov_3
A1: GEESNA | Control de Órdenes de Contenedor - Proveedor 3
A3: Proveedor | B3: Proveedor 3 | D3: Contacto | G3: País | H3: China | J3: Responsable
A4: Órdenes | D4: Monto total | G4: Completas | J4: Activas | M4: En rojo | P4: % avance prom. | S4: Próx. ETA bodega
A5: =COUNTIF(A11:A40,"<>") -> 30 | D5: =SUM(E11:E40) -> 0 | G5: =COUNTIF(R11:R40,"COMPLETA") -> 0 | J5: =COUNTIFS(R11:R40,"<>COMPLETA",A11:A40,"<>") -> 30 | M5: =COUNTIF(T11:T40,"ROJO") -> 0 | P5: =IFERROR(AVERAGE(S11:S40),0) -> 0 | S5: =IFERROR(MINIFS(G11:G40,R11:R40,"<>COMPLETA",G11:G40,">0"),0) -> 0
A8: Semáforo proveedor | B8: =IF(J5>0,"ROJO",IF(H5>0,"AMARILLO","VERDE")) -> ROJO | D8: Siguiente acción | E8: =IF(B8="ROJO","Escalar órdenes vencidas",IF(B8="AMARILLO","Monitorear órdenes activas","Operación estable")) -> Escalar órdenes vencidas
A10: Orden ID | B10: Producto / SKU | C10: Contenedor | D10: Responsable | E10: Monto Orden | F10: ETA Puerto MX | G10: ETA Bodega | H10: Cotizar | I10: Aprobar | J10: Info empaque | K10: Anticipo | L10: Producción OK | M10: Sale puerto origen | N10: Llega puerto MX | O10: Llega bodega | P10: Etapa actual | Q10: Estado orden | R10: % avance | S10: Semáforo | T10: Días sin movimiento | U10: Notas
A11: P3-001 | P11: =IF(O11<>"","Llega bodega",IF(N11<>"","Llega puerto MX",IF(M11<>"","Sale puerto origen",IF(L11<>"","Producción OK",IF(K11<>"","Anticipo",IF(J11<>"","Info empaque",IF(I11<>"","Aprobar",IF(H11<>"","Cotizar","Sin iniciar")))))))) -> Sin iniciar | Q11: =IF(A11="","",IF(O11<>"","COMPLETA",IF(M11<>"","EN TRÁNSITO",IF(L11<>"","EN PRODUCCIÓN",IF(K11<>"","PAGADA / EN ESPERA","EN GESTIÓN"))))) -> EN GESTIÓN | R11: =COUNT(H11:O11)/8 -> 0 | S11: =IF(A11="","",IF(O11<>"","VERDE",IF(AND(G11<>"",TODAY()>G11),"ROJO",IF(COUNT(H11:O11)=0,"GRIS","AMARILLO")))) -> GRIS | T11: =IF(COUNT(H11:O11)=0,"",TODAY()-MAX(H11:O11))
A12: P3-002 | P12: =IF(O12<>"","Llega bodega",IF(N12<>"","Llega puerto MX",IF(M12<>"","Sale puerto origen",IF(L12<>"","Producción OK",IF(K12<>"","Anticipo",IF(J12<>"","Info empaque",IF(I12<>"","Aprobar",IF(H12<>"","Cotizar","Sin iniciar")))))))) -> Sin iniciar | Q12: =IF(A12="","",IF(O12<>"","COMPLETA",IF(M12<>"","EN TRÁNSITO",IF(L12<>"","EN PRODUCCIÓN",IF(K12<>"","PAGADA / EN ESPERA","EN GESTIÓN"))))) -> EN GESTIÓN | R12: =COUNT(H12:O12)/8 -> 0 | S12: =IF(A12="","",IF(O12<>"","VERDE",IF(AND(G12<>"",TODAY()>G12),"ROJO",IF(COUNT(H12:O12)=0,"GRIS","AMARILLO")))) -> GRIS | T12: =IF(COUNT(H12:O12)=0,"",TODAY()-MAX(H12:O12))
A13: P3-003 | P13: =IF(O13<>"","Llega bodega",IF(N13<>"","Llega puerto MX",IF(M13<>"","Sale puerto origen",IF(L13<>"","Producción OK",IF(K13<>"","Anticipo",IF(J13<>"","Info empaque",IF(I13<>"","Aprobar",IF(H13<>"","Cotizar","Sin iniciar")))))))) -> Sin iniciar | Q13: =IF(A13="","",IF(O13<>"","COMPLETA",IF(M13<>"","EN TRÁNSITO",IF(L13<>"","EN PRODUCCIÓN",IF(K13<>"","PAGADA / EN ESPERA","EN GESTIÓN"))))) -> EN GESTIÓN | R13: =COUNT(H13:O13)/8 -> 0 | S13: =IF(A13="","",IF(O13<>"","VERDE",IF(AND(G13<>"",TODAY()>G13),"ROJO",IF(COUNT(H13:O13)=0,"GRIS","AMARILLO")))) -> GRIS | T13: =IF(COUNT(H13:O13)=0,"",TODAY()-MAX(H13:O13))
A14: P3-004 | P14: =IF(O14<>"","Llega bodega",IF(N14<>"","Llega puerto MX",IF(M14<>"","Sale puerto origen",IF(L14<>"","Producción OK",IF(K14<>"","Anticipo",IF(J14<>"","Info empaque",IF(I14<>"","Aprobar",IF(H14<>"","Cotizar","Sin iniciar")))))))) -> Sin iniciar | Q14: =IF(A14="","",IF(O14<>"","COMPLETA",IF(M14<>"","EN TRÁNSITO",IF(L14<>"","EN PRODUCCIÓN",IF(K14<>"","PAGADA / EN ESPERA","EN GESTIÓN"))))) -> EN GESTIÓN | R14: =COUNT(H14:O14)/8 -> 0 | S14: =IF(A14="","",IF(O14<>"","VERDE",IF(AND(G14<>"",TODAY()>G14),"ROJO",IF(COUNT(H14:O14)=0,"GRIS","AMARILLO")))) -> GRIS | T14: =IF(COUNT(H14:O14)=0,"",TODAY()-MAX(H14:O14))
A15: P3-005 | P15: =IF(O15<>"","Llega bodega",IF(N15<>"","Llega puerto MX",IF(M15<>"","Sale puerto origen",IF(L15<>"","Producción OK",IF(K15<>"","Anticipo",IF(J15<>"","Info empaque",IF(I15<>"","Aprobar",IF(H15<>"","Cotizar","Sin iniciar")))))))) -> Sin iniciar | Q15: =IF(A15="","",IF(O15<>"","COMPLETA",IF(M15<>"","EN TRÁNSITO",IF(L15<>"","EN PRODUCCIÓN",IF(K15<>"","PAGADA / EN ESPERA","EN GESTIÓN"))))) -> EN GESTIÓN | R15: =COUNT(H15:O15)/8 -> 0 | S15: =IF(A15="","",IF(O15<>"","VERDE",IF(AND(G15<>"",TODAY()>G15),"ROJO",IF(COUNT(H15:O15)=0,"GRIS","AMARILLO")))) -> GRIS | T15: =IF(COUNT(H15:O15)=0,"",TODAY()-MAX(H15:O15))
A16: P3-006 | P16: =IF(O16<>"","Llega bodega",IF(N16<>"","Llega puerto MX",IF(M16<>"","Sale puerto origen",IF(L16<>"","Producción OK",IF(K16<>"","Anticipo",IF(J16<>"","Info empaque",IF(I16<>"","Aprobar",IF(H16<>"","Cotizar","Sin iniciar")))))))) -> Sin iniciar | Q16: =IF(A16="","",IF(O16<>"","COMPLETA",IF(M16<>"","EN TRÁNSITO",IF(L16<>"","EN PRODUCCIÓN",IF(K16<>"","PAGADA / EN ESPERA","EN GESTIÓN"))))) -> EN GESTIÓN | R16: =COUNT(H16:O16)/8 -> 0 | S16: =IF(A16="","",IF(O16<>"","VERDE",IF(AND(G16<>"",TODAY()>G16),"ROJO",IF(COUNT(H16:O16)=0,"GRIS","AMARILLO")))) -> GRIS | T16: =IF(COUNT(H16:O16)=0,"",TODAY()-MAX(H16:O16))
A17: P3-007 | P17: =IF(O17<>"","Llega bodega",IF(N17<>"","Llega puerto MX",IF(M17<>"","Sale puerto origen",IF(L17<>"","Producción OK",IF(K17<>"","Anticipo",IF(J17<>"","Info empaque",IF(I17<>"","Aprobar",IF(H17<>"","Cotizar","Sin iniciar")))))))) -> Sin iniciar | Q17: =IF(A17="","",IF(O17<>"","COMPLETA",IF(M17<>"","EN TRÁNSITO",IF(L17<>"","EN PRODUCCIÓN",IF(K17<>"","PAGADA / EN ESPERA","EN GESTIÓN"))))) -> EN GESTIÓN | R17: =COUNT(H17:O17)/8 -> 0 | S17: =IF(A17="","",IF(O17<>"","VERDE",IF(AND(G17<>"",TODAY()>G17),"ROJO",IF(COUNT(H17:O17)=0,"GRIS","AMARILLO")))) -> GRIS | T17: =IF(COUNT(H17:O17)=0,"",TODAY()-MAX(H17:O17))
A18: P3-008 | P18: =IF(O18<>"","Llega bodega",IF(N18<>"","Llega puerto MX",IF(M18<>"","Sale puerto origen",IF(L18<>"","Producción OK",IF(K18<>"","Anticipo",IF(J18<>"","Info empaque",IF(I18<>"","Aprobar",IF(H18<>"","Cotizar","Sin iniciar")))))))) -> Sin iniciar | Q18: =IF(A18="","",IF(O18<>"","COMPLETA",IF(M18<>"","EN TRÁNSITO",IF(L18<>"","EN PRODUCCIÓN",IF(K18<>"","PAGADA / EN ESPERA","EN GESTIÓN"))))) -> EN GESTIÓN | R18: =COUNT(H18:O18)/8 -> 0 | S18: =IF(A18="","",IF(O18<>"","VERDE",IF(AND(G18<>"",TODAY()>G18),"ROJO",IF(COUNT(H18:O18)=0,"GRIS","AMARILLO")))) -> GRIS | T18: =IF(COUNT(H18:O18)=0,"",TODAY()-MAX(H18:O18))
A19: P3-009 | P19: =IF(O19<>"","Llega bodega",IF(N19<>"","Llega puerto MX",IF(M19<>"","Sale puerto origen",IF(L19<>"","Producción OK",IF(K19<>"","Anticipo",IF(J19<>"","Info empaque",IF(I19<>"","Aprobar",IF(H19<>"","Cotizar","Sin iniciar")))))))) -> Sin iniciar | Q19: =IF(A19="","",IF(O19<>"","COMPLETA",IF(M19<>"","EN TRÁNSITO",IF(L19<>"","EN PRODUCCIÓN",IF(K19<>"","PAGADA / EN ESPERA","EN GESTIÓN"))))) -> EN GESTIÓN | R19: =COUNT(H19:O19)/8 -> 0 | S19: =IF(A19="","",IF(O19<>"","VERDE",IF(AND(G19<>"",TODAY()>G19),"ROJO",IF(COUNT(H19:O19)=0,"GRIS","AMARILLO")))) -> GRIS | T19: =IF(COUNT(H19:O19)=0,"",TODAY()-MAX(H19:O19))
A20: P3-010 | P20: =IF(O20<>"","Llega bodega",IF(N20<>"","Llega puerto MX",IF(M20<>"","Sale puerto origen",IF(L20<>"","Producción OK",IF(K20<>"","Anticipo",IF(J20<>"","Info empaque",IF(I20<>"","Aprobar",IF(H20<>"","Cotizar","Sin iniciar")))))))) -> Sin iniciar | Q20: =IF(A20="","",IF(O20<>"","COMPLETA",IF(M20<>"","EN TRÁNSITO",IF(L20<>"","EN PRODUCCIÓN",IF(K20<>"","PAGADA / EN ESPERA","EN GESTIÓN"))))) -> EN GESTIÓN | R20: =COUNT(H20:O20)/8 -> 0 | S20: =IF(A20="","",IF(O20<>"","VERDE",IF(AND(G20<>"",TODAY()>G20),"ROJO",IF(COUNT(H20:O20)=0,"GRIS","AMARILLO")))) -> GRIS | T20: =IF(COUNT(H20:O20)=0,"",TODAY()-MAX(H20:O20))
A21: P3-011 | P21: =IF(O21<>"","Llega bodega",IF(N21<>"","Llega puerto MX",IF(M21<>"","Sale puerto origen",IF(L21<>"","Producción OK",IF(K21<>"","Anticipo",IF(J21<>"","Info empaque",IF(I21<>"","Aprobar",IF(H21<>"","Cotizar","Sin iniciar")))))))) -> Sin iniciar | Q21: =IF(A21="","",IF(O21<>"","COMPLETA",IF(M21<>"","EN TRÁNSITO",IF(L21<>"","EN PRODUCCIÓN",IF(K21<>"","PAGADA / EN ESPERA","EN GESTIÓN"))))) -> EN GESTIÓN | R21: =COUNT(H21:O21)/8 -> 0 | S21: =IF(A21="","",IF(O21<>"","VERDE",IF(AND(G21<>"",TODAY()>G21),"ROJO",IF(COUNT(H21:O21)=0,"GRIS","AMARILLO")))) -> GRIS | T21: =IF(COUNT(H21:O21)=0,"",TODAY()-MAX(H21:O21))
A22: P3-012 | P22: =IF(O22<>"","Llega bodega",IF(N22<>"","Llega puerto MX",IF(M22<>"","Sale puerto origen",IF(L22<>"","Producción OK",IF(K22<>"","Anticipo",IF(J22<>"","Info empaque",IF(I22<>"","Aprobar",IF(H22<>"","Cotizar","Sin iniciar")))))))) -> Sin iniciar | Q22: =IF(A22="","",IF(O22<>"","COMPLETA",IF(M22<>"","EN TRÁNSITO",IF(L22<>"","EN PRODUCCIÓN",IF(K22<>"","PAGADA / EN ESPERA","EN GESTIÓN"))))) -> EN GESTIÓN | R22: =COUNT(H22:O22)/8 -> 0 | S22: =IF(A22="","",IF(O22<>"","VERDE",IF(AND(G22<>"",TODAY()>G22),"ROJO",IF(COUNT(H22:O22)=0,"GRIS","AMARILLO")))) -> GRIS | T22: =IF(COUNT(H22:O22)=0,"",TODAY()-MAX(H22:O22))
... A40: P3-030 | P40: =IF(O40<>"","Llega bodega",IF(N40<>"","Llega puerto MX",IF(M40<>"","Sale puerto origen",IF(L40<>"","Producción OK",IF(K40<>"","Anticipo",IF(J40<>"","Info empaque",IF(I40<>"","Aprobar",IF(H40<>"","Cotizar","Sin iniciar")))))))) -> Sin iniciar | Q40: =IF(A40="","",IF(O40<>"","COMPLETA",IF(M40<>"","EN TRÁNSITO",IF(L40<>"","EN PRODUCCIÓN",IF(K40<>"","PAGADA / EN ESPERA","EN GESTIÓN"))))) -> EN GESTIÓN | R40: =COUNT(H40:O40)/8 -> 0 | S40: =IF(A40="","",IF(O40<>"","VERDE",IF(AND(G40<>"",TODAY()>G40),"ROJO",IF(COUNT(H40:O40)=0,"GRIS","AMARILLO")))) -> GRIS | T40: =IF(COUNT(H40:O40)=0,"",TODAY()-MAX(H40:O40))
A42: Cómo funciona el semáforo por proceso: | B42: Verde = hito completado | Amarillo = siguiente hito a ejecutar | Gris = hito futuro | Rojo = la orden ya venció vs ETA Bodega
A43: Tip: | B43: Captura fechas reales en los hitos H:O. El dashboard se actualiza solo.

Sheet Prov_4
A1: GEESNA | Control de Órdenes de Contenedor - Proveedor 4
A3: Proveedor | B3: Proveedor 4 | D3: Contacto | G3: País | H3: China | J3: Responsable
A4: Órdenes | D4: Monto total | G4: Completas | J4: Activas | M4: En rojo | P4: % avance prom. | S4: Próx. ETA bodega
A5: =COUNTIF(A11:A40,"<>") -> 30 | D5: =SUM(E11:E40) -> 0 | G5: =COUNTIF(R11:R40,"COMPLETA") -> 0 | J5: =COUNTIFS(R11:R40,"<>COMPLETA",A11:A40,"<>") -> 30 | M5: =COUNTIF(T11:T40,"ROJO") -> 0 | P5: =IFERROR(AVERAGE(S11:S40),0) -> 0 | S5: =IFERROR(MINIFS(G11:G40,R11:R40,"<>COMPLETA",G11:G40,">0"),0) -> 0
A8: Semáforo proveedor | B8: =IF(J5>0,"ROJO",IF(H5>0,"AMARILLO","VERDE")) -> ROJO | D8: Siguiente acción | E8: =IF(B8="ROJO","Escalar órdenes vencidas",IF(B8="AMARILLO","Monitorear órdenes activas","Operación estable")) -> Escalar órdenes vencidas
A10: Orden ID | B10: Producto / SKU | C10: Contenedor | D10: Responsable | E10: Monto Orden | F10: ETA Puerto MX | G10: ETA Bodega | H10: Cotizar | I10: Aprobar | J10: Info empaque | K10: Anticipo | L10: Producción OK | M10: Sale puerto origen | N10: Llega puerto MX | O10: Llega bodega | P10: Etapa actual | Q10: Estado orden | R10: % avance | S10: Semáforo | T10: Días sin movimiento | U10: Notas
A11: P4-001 | P11: =IF(O11<>"","Llega bodega",IF(N11<>"","Llega puerto MX",IF(M11<>"","Sale puerto origen",IF(L11<>"","Producción OK",IF(K11<>"","Anticipo",IF(J11<>"","Info empaque",IF(I11<>"","Aprobar",IF(H11<>"","Cotizar","Sin iniciar")))))))) -> Sin iniciar | Q11: =IF(A11="","",IF(O11<>"","COMPLETA",IF(M11<>"","EN TRÁNSITO",IF(L11<>"","EN PRODUCCIÓN",IF(K11<>"","PAGADA / EN ESPERA","EN GESTIÓN"))))) -> EN GESTIÓN | R11: =COUNT(H11:O11)/8 -> 0 | S11: =IF(A11="","",IF(O11<>"","VERDE",IF(AND(G11<>"",TODAY()>G11),"ROJO",IF(COUNT(H11:O11)=0,"GRIS","AMARILLO")))) -> GRIS | T11: =IF(COUNT(H11:O11)=0,"",TODAY()-MAX(H11:O11))
A12: P4-002 | P12: =IF(O12<>"","Llega bodega",IF(N12<>"","Llega puerto MX",IF(M12<>"","Sale puerto origen",IF(L12<>"","Producción OK",IF(K12<>"","Anticipo",IF(J12<>"","Info empaque",IF(I12<>"","Aprobar",IF(H12<>"","Cotizar","Sin iniciar")))))))) -> Sin iniciar | Q12: =IF(A12="","",IF(O12<>"","COMPLETA",IF(M12<>"","EN TRÁNSITO",IF(L12<>"","EN PRODUCCIÓN",IF(K12<>"","PAGADA / EN ESPERA","EN GESTIÓN"))))) -> EN GESTIÓN | R12: =COUNT(H12:O12)/8 -> 0 | S12: =IF(A12="","",IF(O12<>"","VERDE",IF(AND(G12<>"",TODAY()>G12),"ROJO",IF(COUNT(H12:O12)=0,"GRIS","AMARILLO")))) -> GRIS | T12: =IF(COUNT(H12:O12)=0,"",TODAY()-MAX(H12:O12))
A13: P4-003 | P13: =IF(O13<>"","Llega bodega",IF(N13<>"","Llega puerto MX",IF(M13<>"","Sale puerto origen",IF(L13<>"","Producción OK",IF(K13<>"","Anticipo",IF(J13<>"","Info empaque",IF(I13<>"","Aprobar",IF(H13<>"","Cotizar","Sin iniciar")))))))) -> Sin iniciar | Q13: =IF(A13="","",IF(O13<>"","COMPLETA",IF(M13<>"","EN TRÁNSITO",IF(L13<>"","EN PRODUCCIÓN",IF(K13<>"","PAGADA / EN ESPERA","EN GESTIÓN"))))) -> EN GESTIÓN | R13: =COUNT(H13:O13)/8 -> 0 | S13: =IF(A13="","",IF(O13<>"","VERDE",IF(AND(G13<>"",TODAY()>G13),"ROJO",IF(COUNT(H13:O13)=0,"GRIS","AMARILLO")))) -> GRIS | T13: =IF(COUNT(H13:O13)=0,"",TODAY()-MAX(H13:O13))
A14: P4-004 | P14: =IF(O14<>"","Llega bodega",IF(N14<>"","Llega puerto MX",IF(M14<>"","Sale puerto origen",IF(L14<>"","Producción OK",IF(K14<>"","Anticipo",IF(J14<>"","Info empaque",IF(I14<>"","Aprobar",IF(H14<>"","Cotizar","Sin iniciar")))))))) -> Sin iniciar | Q14: =IF(A14="","",IF(O14<>"","COMPLETA",IF(M14<>"","EN TRÁNSITO",IF(L14<>"","EN PRODUCCIÓN",IF(K14<>"","PAGADA / EN ESPERA","EN GESTIÓN"))))) -> EN GESTIÓN | R14: =COUNT(H14:O14)/8 -> 0 | S14: =IF(A14="","",IF(O14<>"","VERDE",IF(AND(G14<>"",TODAY()>G14),"ROJO",IF(COUNT(H14:O14)=0,"GRIS","AMARILLO")))) -> GRIS | T14: =IF(COUNT(H14:O14)=0,"",TODAY()-MAX(H14:O14))
A15: P4-005 | P15: =IF(O15<>"","Llega bodega",IF(N15<>"","Llega puerto MX",IF(M15<>"","Sale puerto origen",IF(L15<>"","Producción OK",IF(K15<>"","Anticipo",IF(J15<>"","Info empaque",IF(I15<>"","Aprobar",IF(H15<>"","Cotizar","Sin iniciar")))))))) -> Sin iniciar | Q15: =IF(A15="","",IF(O15<>"","COMPLETA",IF(M15<>"","EN TRÁNSITO",IF(L15<>"","EN PRODUCCIÓN",IF(K15<>"","PAGADA / EN ESPERA","EN GESTIÓN"))))) -> EN GESTIÓN | R15: =COUNT(H15:O15)/8 -> 0 | S15: =IF(A15="","",IF(O15<>"","VERDE",IF(AND(G15<>"",TODAY()>G15),"ROJO",IF(COUNT(H15:O15)=0,"GRIS","AMARILLO")))) -> GRIS | T15: =IF(COUNT(H15:O15)=0,"",TODAY()-MAX(H15:O15))
A16: P4-006 | P16: =IF(O16<>"","Llega bodega",IF(N16<>"","Llega puerto MX",IF(M16<>"","Sale puerto origen",IF(L16<>"","Producción OK",IF(K16<>"","Anticipo",IF(J16<>"","Info empaque",IF(I16<>"","Aprobar",IF(H16<>"","Cotizar","Sin iniciar")))))))) -> Sin iniciar | Q16: =IF(A16="","",IF(O16<>"","COMPLETA",IF(M16<>"","EN TRÁNSITO",IF(L16<>"","EN PRODUCCIÓN",IF(K16<>"","PAGADA / EN ESPERA","EN GESTIÓN"))))) -> EN GESTIÓN | R16: =COUNT(H16:O16)/8 -> 0 | S16: =IF(A16="","",IF(O16<>"","VERDE",IF(AND(G16<>"",TODAY()>G16),"ROJO",IF(COUNT(H16:O16)=0,"GRIS","AMARILLO")))) -> GRIS | T16: =IF(COUNT(H16:O16)=0,"",TODAY()-MAX(H16:O16))
A17: P4-007 | P17: =IF(O17<>"","Llega bodega",IF(N17<>"","Llega puerto MX",IF(M17<>"","Sale puerto origen",IF(L17<>"","Producción OK",IF(K17<>"","Anticipo",IF(J17<>"","Info empaque",IF(I17<>"","Aprobar",IF(H17<>"","Cotizar","Sin iniciar")))))))) -> Sin iniciar | Q17: =IF(A17="","",IF(O17<>"","COMPLETA",IF(M17<>"","EN TRÁNSITO",IF(L17<>"","EN PRODUCCIÓN",IF(K17<>"","PAGADA / EN ESPERA","EN GESTIÓN"))))) -> EN GESTIÓN | R17: =COUNT(H17:O17)/8 -> 0 | S17: =IF(A17="","",IF(O17<>"","VERDE",IF(AND(G17<>"",TODAY()>G17),"ROJO",IF(COUNT(H17:O17)=0,"GRIS","AMARILLO")))) -> GRIS | T17: =IF(COUNT(H17:O17)=0,"",TODAY()-MAX(H17:O17))
A18: P4-008 | P18: =IF(O18<>"","Llega bodega",IF(N18<>"","Llega puerto MX",IF(M18<>"","Sale puerto origen",IF(L18<>"","Producción OK",IF(K18<>"","Anticipo",IF(J18<>"","Info empaque",IF(I18<>"","Aprobar",IF(H18<>"","Cotizar","Sin iniciar")))))))) -> Sin iniciar | Q18: =IF(A18="","",IF(O18<>"","COMPLETA",IF(M18<>"","EN TRÁNSITO",IF(L18<>"","EN PRODUCCIÓN",IF(K18<>"","PAGADA / EN ESPERA","EN GESTIÓN"))))) -> EN GESTIÓN | R18: =COUNT(H18:O18)/8 -> 0 | S18: =IF(A18="","",IF(O18<>"","VERDE",IF(AND(G18<>"",TODAY()>G18),"ROJO",IF(COUNT(H18:O18)=0,"GRIS","AMARILLO")))) -> GRIS | T18: =IF(COUNT(H18:O18)=0,"",TODAY()-MAX(H18:O18))
A19: P4-009 | P19: =IF(O19<>"","Llega bodega",IF(N19<>"","Llega puerto MX",IF(M19<>"","Sale puerto origen",IF(L19<>"","Producción OK",IF(K19<>"","Anticipo",IF(J19<>"","Info empaque",IF(I19<>"","Aprobar",IF(H19<>"","Cotizar","Sin iniciar")))))))) -> Sin iniciar | Q19: =IF(A19="","",IF(O19<>"","COMPLETA",IF(M19<>"","EN TRÁNSITO",IF(L19<>"","EN PRODUCCIÓN",IF(K19<>"","PAGADA / EN ESPERA","EN GESTIÓN"))))) -> EN GESTIÓN | R19: =COUNT(H19:O19)/8 -> 0 | S19: =IF(A19="","",IF(O19<>"","VERDE",IF(AND(G19<>"",TODAY()>G19),"ROJO",IF(COUNT(H19:O19)=0,"GRIS","AMARILLO")))) -> GRIS | T19: =IF(COUNT(H19:O19)=0,"",TODAY()-MAX(H19:O19))
A20: P4-010 | P20: =IF(O20<>"","Llega bodega",IF(N20<>"","Llega puerto MX",IF(M20<>"","Sale puerto origen",IF(L20<>"","Producción OK",IF(K20<>"","Anticipo",IF(J20<>"","Info empaque",IF(I20<>"","Aprobar",IF(H20<>"","Cotizar","Sin iniciar")))))))) -> Sin iniciar | Q20: =IF(A20="","",IF(O20<>"","COMPLETA",IF(M20<>"","EN TRÁNSITO",IF(L20<>"","EN PRODUCCIÓN",IF(K20<>"","PAGADA / EN ESPERA","EN GESTIÓN"))))) -> EN GESTIÓN | R20: =COUNT(H20:O20)/8 -> 0 | S20: =IF(A20="","",IF(O20<>"","VERDE",IF(AND(G20<>"",TODAY()>G20),"ROJO",IF(COUNT(H20:O20)=0,"GRIS","AMARILLO")))) -> GRIS | T20: =IF(COUNT(H20:O20)=0,"",TODAY()-MAX(H20:O20))
A21: P4-011 | P21: =IF(O21<>"","Llega bodega",IF(N21<>"","Llega puerto MX",IF(M21<>"","Sale puerto origen",IF(L21<>"","Producción OK",IF(K21<>"","Anticipo",IF(J21<>"","Info empaque",IF(I21<>"","Aprobar",IF(H21<>"","Cotizar","Sin iniciar")))))))) -> Sin iniciar | Q21: =IF(A21="","",IF(O21<>"","COMPLETA",IF(M21<>"","EN TRÁNSITO",IF(L21<>"","EN PRODUCCIÓN",IF(K21<>"","PAGADA / EN ESPERA","EN GESTIÓN"))))) -> EN GESTIÓN | R21: =COUNT(H21:O21)/8 -> 0 | S21: =IF(A21="","",IF(O21<>"","VERDE",IF(AND(G21<>"",TODAY()>G21),"ROJO",IF(COUNT(H21:O21)=0,"GRIS","AMARILLO")))) -> GRIS | T21: =IF(COUNT(H21:O21)=0,"",TODAY()-MAX(H21:O21))
A22: P4-012 | P22: =IF(O22<>"","Llega bodega",IF(N22<>"","Llega puerto MX",IF(M22<>"","Sale puerto origen",IF(L22<>"","Producción OK",IF(K22<>"","Anticipo",IF(J22<>"","Info empaque",IF(I22<>"","Aprobar",IF(H22<>"","Cotizar","Sin iniciar")))))))) -> Sin iniciar | Q22: =IF(A22="","",IF(O22<>"","COMPLETA",IF(M22<>"","EN TRÁNSITO",IF(L22<>"","EN PRODUCCIÓN",IF(K22<>"","PAGADA / EN ESPERA","EN GESTIÓN"))))) -> EN GESTIÓN | R22: =COUNT(H22:O22)/8 -> 0 | S22: =IF(A22="","",IF(O22<>"","VERDE",IF(AND(G22<>"",TODAY()>G22),"ROJO",IF(COUNT(H22:O22)=0,"GRIS","AMARILLO")))) -> GRIS | T22: =IF(COUNT(H22:O22)=0,"",TODAY()-MAX(H22:O22))
... A40: P4-030 | P40: =IF(O40<>"","Llega bodega",IF(N40<>"","Llega puerto MX",IF(M40<>"","Sale puerto origen",IF(L40<>"","Producción OK",IF(K40<>"","Anticipo",IF(J40<>"","Info empaque",IF(I40<>"","Aprobar",IF(H40<>"","Cotizar","Sin iniciar")))))))) -> Sin iniciar | Q40: =IF(A40="","",IF(O40<>"","COMPLETA",IF(M40<>"","EN TRÁNSITO",IF(L40<>"","EN PRODUCCIÓN",IF(K40<>"","PAGADA / EN ESPERA","EN GESTIÓN"))))) -> EN GESTIÓN | R40: =COUNT(H40:O40)/8 -> 0 | S40: =IF(A40="","",IF(O40<>"","VERDE",IF(AND(G40<>"",TODAY()>G40),"ROJO",IF(COUNT(H40:O40)=0,"GRIS","AMARILLO")))) -> GRIS | T40: =IF(COUNT(H40:O40)=0,"",TODAY()-MAX(H40:O40))
A42: Cómo funciona el semáforo por proceso: | B42: Verde = hito completado | Amarillo = siguiente hito a ejecutar | Gris = hito futuro | Rojo = la orden ya venció vs ETA Bodega
A43: Tip: | B43: Captura fechas reales en los hitos H:O. El dashboard se actualiza solo.

Sheet Prov_5
A1: GEESNA | Control de Órdenes de Contenedor - Proveedor 5
A3: Proveedor | B3: Proveedor 5 | D3: Contacto | G3: País | H3: China | J3: Responsable
A4: Órdenes | D4: Monto total | G4: Completas | J4: Activas | M4: En rojo | P4: % avance prom. | S4: Próx. ETA bodega
A5: =COUNTIF(A11:A40,"<>") -> 30 | D5: =SUM(E11:E40) -> 0 | G5: =COUNTIF(R11:R40,"COMPLETA") -> 0 | J5: =COUNTIFS(R11:R40,"<>COMPLETA",A11:A40,"<>") -> 30 | M5: =COUNTIF(T11:T40,"ROJO") -> 0 | P5: =IFERROR(AVERAGE(S11:S40),0) -> 0 | S5: =IFERROR(MINIFS(G11:G40,R11:R40,"<>COMPLETA",G11:G40,">0"),0) -> 0
A8: Semáforo proveedor | B8: =IF(J5>0,"ROJO",IF(H5>0,"AMARILLO","VERDE")) -> ROJO | D8: Siguiente acción | E8: =IF(B8="ROJO","Escalar órdenes vencidas",IF(B8="AMARILLO","Monitorear órdenes activas","Operación estable")) -> Escalar órdenes vencidas
A10: Orden ID | B10: Producto / SKU | C10: Contenedor | D10: Responsable | E10: Monto Orden | F10: ETA Puerto MX | G10: ETA Bodega | H10: Cotizar | I10: Aprobar | J10: Info empaque | K10: Anticipo | L10: Producción OK | M10: Sale puerto origen | N10: Llega puerto MX | O10: Llega bodega | P10: Etapa actual | Q10: Estado orden | R10: % avance | S10: Semáforo | T10: Días sin movimiento | U10: Notas
